<sdf version='1.5'>
	<model name="mpl_haptix_right_forearm">
	<!-- Model SDF copied from gazebo_models -->
	<joint name='elbow' type='revolute'>
		<child>forearm</child>
		<parent>world</parent>
		<axis>
			<xyz>0 0 1.0</xyz>
			<use_parent_model_frame>1</use_parent_model_frame>
		</axis>
	</joint>
	<link name='forearm'>
		<pose>0.00660504 -0.294573 0.119123 -1.21334e-13 2.77556e-17 -0.0115373</pose>
	
		<collision name='collision'>
			<pose>0 0 0.02855 0 0 0</pose>
			<geometry>
				<cylinder>
					<radius>0.03567</radius>
					<length>0.0571</length>
				</cylinder>
			</geometry>
	
		</collision>
		<collision name='collision_1'>
			<pose>0 -0.10745 0.016 1.5707 0 0</pose>
				<geometry>
					<cylinder>
						<radius>0.035</radius>
						<length>0.148</length>
					</cylinder>
				</geometry>
	
		</collision>
		<visual name='visual'>
			<geometry>
				<mesh>
					<uri>model://mpl_haptix_right_forearm/meshes/forearm.stl</uri>
				</mesh>
			</geometry>
			<material>
				<script>
					<name>Gazebo/FlatBlack</name>
				</script>
			</material>
		</visual>
	</link>

	<link name='wristy'>
		<pose>0.00449937 -0.479995 0.135123 -1.2164e-13 1.09079e-14 -0.0115373</pose>

		<collision name='collision'>
			<pose>0 -0.025 0 1.5707 0 0</pose>
			<geometry>
				<cylinder>
					<radius>0.03447</radius>
					<length>0.05</length>
				</cylinder>
			</geometry>

		</collision>
		<visual name='visual'>
			<geometry>
				<mesh>
					<uri>model://mpl_haptix_right_forearm/meshes/wristy.stl</uri>
				</mesh>
			</geometry>
			<material>
				<ambient>0.2 0.2 0.2 1</ambient>
				<diffuse>0.8 0.8 0.8 1</diffuse>
				<specular>0.9 0.9 0.9 1</specular>
			</material>
		</visual>
	</link>
	<joint name='wristy' type='revolute'>
		<child>wristy</child>
			<parent>forearm</parent>
			<axis>
				<xyz>0.011537 0.999933 -1.2164e-13</xyz>


				<use_parent_model_frame>1</use_parent_model_frame>
			</axis>

	</joint>

	<link name='wristx'>
		<pose>0.003916 -0.527636 0.137161 -1.18962e-13 1.21847e-14 -0.0115373</pose>

		<collision name='collision'>
			<pose>0 0 -0.00314 0 0 0</pose>
			<geometry>
				<cylinder>
					<radius>0.01473</radius>
					<length>0.04478</length>
				</cylinder>
			</geometry>

		</collision>
		<collision name='collision_1'>
			<pose>0.02360 -0.02969 -0.00240 0 1.5707 0</pose>
			<geometry>
				<cylinder>
					<radius>0.013175</radius>
					<length>0.005</length>
				</cylinder>
			</geometry>

		</collision>
		<collision name='collision_2'>
			<pose>-0.02360 -0.02969 -0.00240 0 1.5707 0</pose>
			<geometry>
				<cylinder>
					<radius>0.013175</radius>
					<length>0.005</length>
				</cylinder>
			</geometry>

		</collision>
		<visual name='visual'>
			<geometry>
				<mesh>
					<uri>model://mpl_haptix_right_forearm/meshes/wristx.stl</uri>
				</mesh>
			</geometry>
			<material>
				<ambient>0.2 0.2 0.2 1</ambient>
				<diffuse>0.8 0.8 0.8 1</diffuse>
				<specular>0.9 0.9 0.9 1</specular>
			</material>
		</visual>
	</link>
	<joint name='wristx' type='revolute'>
<child>wristx</child>
<parent>wristy</parent>
<axis>
<xyz>-1.35564e-14 -1.18814e-13 -1</xyz>


<use_parent_model_frame>1</use_parent_model_frame>
</axis>

</joint>

<link name='wristz'>
<pose>0.00375708 -0.557636 0.135067 -2.87105e-13 1.42109e-14 -0.0115373</pose>

<collision name='collision'>
<pose>0.00207 -0.00047 0.00046 1.5707 0 1.5707</pose>
<geometry>
<cylinder>
<radius>0.01411</radius>
<length>0.04482</length>
</cylinder>
</geometry>

</collision>
<collision name='collision_palm'>
<max_contacts>4</max_contacts>
<pose>0.002 -0.03739 0 0 0 0</pose>
<geometry>
<box>
<size>0.07928 0.08316 0.04402</size>
</box>
</geometry>

</collision>
<collision name="palmEdge">
<max_contacts>4</max_contacts>
<pose>-0.028 -0.03 0 1.57 0 -0.1</pose>
<geometry>
<cylinder>
<radius>0.01</radius>
<length>0.060</length>
</cylinder>
</geometry>

</collision>
 <!-- Dorsal surface (top) -->
<collision name="handTop">
<max_contacts>4</max_contacts>
<pose>0.002 -0.045 0.01 0 0 0</pose>
<geometry>
<box>
<size>0.075 0.08 0.02</size>
</box>
</geometry>

</collision>
<!-- Palm 0 (closer to thumb) -->
<collision name="palm0">
<max_contacts>4</max_contacts>
<pose>0.023 -0.04 -0.012 0 0 0.1</pose>
<geometry>
<box>
<size>0.037 0.07 0.02</size>
</box>
</geometry>

</collision>
<!-- Palm 1 (closer to pinky) -->
<collision name="palm1">
<max_contacts>4</max_contacts>
<pose>-0.018 -0.04 -0.012 0 0 0</pose>
<geometry>
<box>
<size>0.037 0.07 0.02</size>
</box>
</geometry>

</collision>
<visual name='visual'>
<geometry>
<mesh>
<uri>model://mpl_haptix_right_forearm/meshes/wristz.stl</uri>
</mesh>
</geometry>
<material>
<ambient>0.2 0.2 0.2 1</ambient>
<diffuse>0.8 0.8 0.8 1</diffuse>
<specular>0.9 0.9 0.9 1</specular>
</material>
</visual>
<visual name='visual_palm'>
<pose>0.025625 0 0 1.7427e-13 8.3267e-17 -3.1876e-16</pose>
<geometry>
<mesh>
<uri>model://mpl_haptix_right_forearm/meshes/palm.stl</uri>
</mesh>
</geometry>
<material>
<script>
<name>Gazebo/FlatBlack</name>
</script>
</material>
</visual>
<!--sensor name='palm0_contact_sensor' type='contact'>
<always_on>1</always_on>
<contact>
<collision>palm0</collision>
</contact>
</sensor-->
<!--sensor name='palm1_contact_sensor' type='contact'>
<always_on>1</always_on>
<contact>
<collision>palm1</collision>
</contact>
</sensor-->
<!--sensor name='palmEdge_contact_sensor' type='contact'>
<always_on>1</always_on>
<contact>
<collision>palmEdge</collision>
</contact>
</sensor-->
<!--sensor name='handTop_contact_sensor' type='contact'>
<always_on>1</always_on>
<contact>
<collision>handTop</collision>
</contact>
</sensor-->
</link>
<joint name='wristz' type='revolute'>
<child>wristz</child>
<parent>wristx</parent>
<axis>
<xyz>0.999933 -0.011537 -1.42109e-14</xyz>


<use_parent_model_frame>1</use_parent_model_frame>
</axis>

</joint>

<link name='index0'>
<pose>0.0384854 -0.623842 0.136079 -1.14726e-13 0.174533 -0.0115373</pose>

<collision name='collision'>
<max_contacts>1</max_contacts>
<pose>0 -0.01339 0 1.5707 0 0</pose>
<geometry>
<cylinder>
<length>0.028</length>
<radius>0.01</radius>
</cylinder>
</geometry>

</collision>
<visual name='visual'>
<geometry>
<mesh>
<uri>model://mpl_haptix_right_forearm/meshes/index0.stl</uri>
</mesh>
</geometry>
<material>
<script>
<name>Gazebo/FlatBlack</name>
</script>
</material>
</visual>
</link>
<joint name='index0' type='revolute'>
<child>index0</child>
<parent>wristz</parent>
<axis>
<xyz>-0.173637 0.00200338 -0.984808</xyz>


<use_parent_model_frame>1</use_parent_model_frame>
</axis>

</joint>

<link name='index1'>
<pose>0.0383394 -0.641841 0.136068 -1.1474e-13 0.174533 -0.0115373</pose>

<collision name='collision'>
<max_contacts>2</max_contacts>
<pose>0 -0.02782 0 1.5707 0 0</pose>
<geometry>
<cylinder>
<radius>0.01</radius>
<length>0.02781</length>
</cylinder>
</geometry>

</collision>
<visual name='visual'>
<geometry>
<mesh>
<uri>model://mpl_haptix_right_forearm/meshes/index1.stl</uri>
</mesh>
</geometry>
<material>
<script>
<name>Gazebo/FlatBlack</name>
</script>
</material>
</visual>
<!--sensor name='index1_contact_sensor' type='contact'>
<always_on>1</always_on>
<contact>
<collision>collision</collision>
</contact>
</sensor-->
</link>
<joint name='index1' type='revolute'>
<child>index1</child>
<parent>index0</parent>
<axis>
<xyz>0.984742 -0.0113618 -0.173648</xyz>


<use_parent_model_frame>1</use_parent_model_frame>
</axis>

</joint>

<link name='index2'>
<pose>0.0389938 -0.685352 0.136372 -1.1445e-13 0.174533 -0.0115373</pose>

<collision name='collision'>
<max_contacts>2</max_contacts>
<pose>0 -0.01152 0 1.5707 0 0</pose>
<geometry>
<cylinder>
<length>0.029</length>
<radius>0.0075</radius>
</cylinder>
</geometry>

</collision>
<collision name='collision_1'>
<max_contacts>2</max_contacts>
<pose>0 -0.02502 0 0 0 0</pose>
<geometry>
<sphere>
<radius>0.0075</radius>
</sphere>
</geometry>

</collision>
<visual name='visual'>
<geometry>
<mesh>
<uri>model://mpl_haptix_right_forearm/meshes/index2.stl</uri>
</mesh>
</geometry>
<material>
<script>
<name>Gazebo/FlatBlack</name>
</script>
</material>
</visual>
<!--sensor name='index2_contact_sensor' type='contact'>
<always_on>1</always_on>
<contact>
<collision>collision</collision>
<collision>collision_1</collision>
</contact>
</sensor-->
</link>
<joint name='index2' type='revolute'>
<child>index2</child>
<parent>index1</parent>
<axis>
<xyz>0.984742 -0.0113618 -0.173648</xyz>


<use_parent_model_frame>1</use_parent_model_frame>
</axis>

</joint>

<link name='index3'>
<self_collide>true</self_collide>
<pose>0.0380858 -0.709843 0.136482 -1.15476e-13 0.174533 -0.0115373</pose>

<collision name='collision'>
<max_contacts>1</max_contacts>
<pose>0 -0.00688 0.0001 1.5707 0 0</pose>
<geometry>
<cylinder>
<length>0.01376</length>
<radius>0.0074</radius>
</cylinder>
</geometry>

</collision>
<collision name='collision_1'>
<max_contacts>1</max_contacts>
<pose>0 -0.015 0.0001 0 0 0</pose>
<geometry>
<sphere>
<radius>0.0072</radius>
</sphere>
</geometry>

</collision>
<visual name='visual'>
<geometry>
<mesh>
<uri>model://mpl_haptix_right_forearm/meshes/index3.stl</uri>
</mesh>
</geometry>
<material>
<script>
<name>Gazebo/FlatBlack</name>
</script>
</material>
</visual>
<!--sensor name='index3_contact_sensor' type='contact'>
<always_on>1</always_on>
<contact>
<collision>collision</collision>
<collision>collision_1</collision>
</contact>
</sensor-->
</link>
<joint name='index3' type='revolute'>
<child>index3</child>
<parent>index2</parent>
<axis>
<xyz>0.984742 -0.0113618 -0.173648</xyz>


<use_parent_model_frame>1</use_parent_model_frame>
</axis>

</joint>

<link name='middle0'>
<pose>0.0156685 -0.63568 0.140513 0.0872665 1.4183e-14 -0.0115373</pose>

<collision name='collision'>
<max_contacts>1</max_contacts>
<pose>0 -0.01339 0 1.5707 0 0</pose>
<geometry>
<cylinder>
<length>0.028</length>
<radius>0.01</radius>
</cylinder>
</geometry>

</collision>
<visual name='visual'>
<geometry>
<mesh>
<uri>model://mpl_haptix_right_forearm/meshes/middle0.stl</uri>
</mesh>
</geometry>
<material>
<script>
<name>Gazebo/FlatBlack</name>
</script>
</material>
</visual>
</link>
<joint name='middle0' type='revolute'>
<child>middle0</child>
<parent>wristz</parent>
<axis>
<xyz>0.00100552 0.0871499 -0.996195</xyz>


<use_parent_model_frame>1</use_parent_model_frame>
</axis>

</joint>

<link name='middle1'>
<pose>0.0155242 -0.653612 0.138944 0.0872665 1.43013e-14 -0.0115373</pose>

<collision name='collision'>
<max_contacts>2</max_contacts>
<pose>0 -0.025 0 1.5707 0 0</pose>
<geometry>
<cylinder>
<radius>0.01</radius>
<length>0.03459</length>
</cylinder>
</geometry>

</collision>
<visual name='visual'>
<geometry>
<mesh>
<uri>model://mpl_haptix_right_forearm/meshes/middle1.stl</uri>
</mesh>
</geometry>
<material>
<script>
<name>Gazebo/FlatBlack</name>
</script>
</material>
</visual>
<!--sensor name='middle1_contact_sensor' type='contact'>
<always_on>1</always_on>
<contact>
<collision>collision</collision>
</contact>
</sensor-->
</link>
<joint name='middle1' type='revolute'>
<child>middle1</child>
<parent>middle0</parent>
<axis>
<xyz>0.999933 -0.011537 -1.43013e-14</xyz>


<use_parent_model_frame>1</use_parent_model_frame>
</axis>

</joint>

<link name='middle2'>
<pose>0.0161097 -0.696999 0.135651 0.0872665 1.32728e-14 -0.0115373</pose>

<collision name='collision'>
<max_contacts>2</max_contacts>
<pose>0 -0.01152 0 1.5707 0 0</pose>
<geometry>
<cylinder>
<length>0.029</length>
<radius>0.0075</radius>
</cylinder>
</geometry>

</collision>
<collision name='collision_1'>
<max_contacts>2</max_contacts>
<pose>0 -0.02302 0 0 0 0</pose>
<geometry>
<sphere>
<radius>0.0075</radius>
</sphere>
</geometry>

</collision>
<visual name='visual'>
<geometry>
<mesh>
<uri>model://mpl_haptix_right_forearm/meshes/middle2.stl</uri>
</mesh>
</geometry>
<material>
<script>
<name>Gazebo/FlatBlack</name>
</script>
</material>
</visual>
<!--sensor name='middle2_contact_sensor' type='contact'>
<always_on>1</always_on>
<contact>
<collision>collision</collision>
<collision>collision_1</collision>
</contact>
</sensor-->
</link>
<joint name='middle2' type='revolute'>
<child>middle2</child>
<parent>middle1</parent>
<axis>
<xyz>0.999933 -0.011537 -1.32727e-14</xyz>


<use_parent_model_frame>1</use_parent_model_frame>
</axis>

</joint>

<link name='middle3'>
<self_collide>true</self_collide>
<pose>0.0151931 -0.721397 0.133515 0.0872665 1.51577e-14 -0.0115373</pose>

<collision name='collision'>
<max_contacts>1</max_contacts>
<pose>0 -0.00688 0.0001 1.5707 0 0</pose>
<geometry>
<cylinder>
<length>0.01376</length>
<radius>0.0074</radius>
</cylinder>
</geometry>

</collision>
<collision name='collision_1'>
<max_contacts>1</max_contacts>
<pose>0 -0.015 0.0001 0 0 0</pose>
<geometry>
<sphere>
<radius>0.0072</radius>
</sphere>
</geometry>

</collision>
<visual name='visual'>
<geometry>
<mesh>
<uri>model://mpl_haptix_right_forearm/meshes/middle3.stl</uri>
</mesh>
</geometry>
<material>
<script>
<name>Gazebo/FlatBlack</name>
</script>
</material>
</visual>
<!--sensor name='middle3_contact_sensor' type='contact'>
<always_on>1</always_on>
<contact>
<collision>collision</collision>
<collision>collision_1</collision>
</contact>
</sensor-->
</link>
<joint name='middle3' type='revolute'>
<child>middle3</child>
<parent>middle2</parent>
<axis>
<xyz>0.999933 -0.011537 -1.51577e-14</xyz>


<use_parent_model_frame>1</use_parent_model_frame>
</axis>

</joint>

<link name='pinky0'>
<pose>-0.0275009 -0.61268 0.129428 -1.14942e-13 -0.174533 -0.0115373</pose>

<collision name='collision'>
<max_contacts>1</max_contacts>
<pose>0 -0.01339 0 1.5707 0 0</pose>
<geometry>
<cylinder>
<length>0.028</length>
<radius>0.01</radius>
</cylinder>
</geometry>

</collision>
<visual name='visual'>
<geometry>
<mesh>
<uri>model://mpl_haptix_right_forearm/meshes/pinky0.stl</uri>
</mesh>
</geometry>
<material>
<script>
<name>Gazebo/FlatBlack</name>
</script>
</material>
</visual>
</link>
<joint name='pinky0' type='revolute'>
<child>pinky0</child>
<parent>wristz</parent>
<axis>
<xyz>0.173637 -0.00200338 -0.984808</xyz>


<use_parent_model_frame>1</use_parent_model_frame>
</axis>

</joint>

<link name='pinky1'>
<pose>-0.0276458 -0.630579 0.129439 -1.14943e-13 -0.174533 -0.0115373</pose>

<collision name='collision'>
<max_contacts>2</max_contacts>
<pose>0 -0.02082 0 1.5707 0 0</pose>
<geometry>
<cylinder>
<radius>0.01</radius>
<length>0.02381</length>
</cylinder>
</geometry>

</collision>
<visual name='visual'>
<geometry>
<mesh>
<uri>model://mpl_haptix_right_forearm/meshes/pinky1.stl</uri>
</mesh>
</geometry>
<material>
<script>
<name>Gazebo/FlatBlack</name>
</script>
</material>
</visual>
<!--sensor name='pinky1_contact_sensor' type='contact'>
<always_on>1</always_on>
<contact>
<collision>collision</collision>
</contact>
</sensor-->
</link>
<joint name='pinky1' type='revolute'>
<child>pinky1</child>
<parent>pinky0</parent>
<axis>
<xyz>0.984742 -0.0113618 0.173648</xyz>


<use_parent_model_frame>1</use_parent_model_frame>
</axis>

</joint>

<link name='pinky2'>
<pose>-0.0275441 -0.663582 0.130032 -1.14415e-13 -0.174533 -0.0115373</pose>

<collision name='collision'>
<max_contacts>2</max_contacts>
<pose>0 -0.0076 0 1.5707 0 0</pose>
<geometry>
<cylinder>
<length>0.029</length>
<radius>0.0075</radius>
</cylinder>
</geometry>

</collision>
<visual name='visual'>
<geometry>
<mesh>
<uri>model://mpl_haptix_right_forearm/meshes/pinky2.stl</uri>
</mesh>
</geometry>
<material>
<script>
<name>Gazebo/FlatBlack</name>
</script>
</material>
</visual>
<!--sensor name='pinky2_contact_sensor' type='contact'>
<always_on>1</always_on>
<contact>
<collision>collision</collision>
</contact>
</sensor-->
</link>
<joint name='pinky2' type='revolute'>
<child>pinky2</child>
<parent>pinky1</parent>
<axis>
<xyz>0.984742 -0.0113618 0.173648</xyz>


<use_parent_model_frame>1</use_parent_model_frame>
</axis>

</joint>

<link name='pinky3'>
<self_collide>true</self_collide>
<pose>-0.0277931 -0.681081 0.130023 -1.14622e-13 -0.174533 -0.0115373</pose>

<collision name='collision'>
<max_contacts>1</max_contacts>
<pose>0 -0.00688 0.0001 1.5707 0 0</pose>
<geometry>
<cylinder>
<length>0.01376</length>
<radius>0.0074</radius>
</cylinder>
</geometry>

</collision>
<collision name='collision_1'>
<max_contacts>1</max_contacts>
<pose>0 -0.015 0.0001 0 0 0</pose>
<geometry>
<sphere>
<radius>0.0072</radius>
</sphere>
</geometry>

</collision>
<visual name='visual'>
<geometry>
<mesh>
<uri>model://mpl_haptix_right_forearm/meshes/pinky3.stl</uri>
</mesh>
</geometry>
<material>
<script>
<name>Gazebo/FlatBlack</name>
</script>
</material>
</visual>
<!--sensor name='pinky3_contact_sensor' type='contact'>
<always_on>1</always_on>
<contact>
<collision>collision</collision>
<collision>collision_1</collision>
</contact>
</sensor-->
</link>
<joint name='pinky3' type='revolute'>
<child>pinky3</child>
<parent>pinky2</parent>
<axis>
<xyz>0.984742 -0.0113618 0.173648</xyz>


<use_parent_model_frame>1</use_parent_model_frame>
</axis>

</joint>

<link name='ring0'>
<pose>-0.00687963 -0.624218 0.136579 -1.14553e-13 -0.174533 -0.0115373</pose>

<collision name='collision'>
<max_contacts>1</max_contacts>
<pose>0 -0.01339 0 1.5707 0 0</pose>
<geometry>
<cylinder>
<length>0.028</length>
<radius>0.01</radius>
</cylinder>
</geometry>

</collision>
<visual name='visual'>
<geometry>
<mesh>
<uri>model://mpl_haptix_right_forearm/meshes/ring0.stl</uri>
</mesh>
</geometry>
<material>
<script>
<name>Gazebo/FlatBlack</name>
</script>
</material>
</visual>
</link>
<joint name='ring0' type='revolute'>
<child>ring0</child>
<parent>wristz</parent>
<axis>
<xyz>0.173637 -0.00200338 -0.984808</xyz>


<use_parent_model_frame>1</use_parent_model_frame>
</axis>

</joint>

<link name='ring1'>
<pose>-0.00702565 -0.642218 0.13659 -1.14538e-13 -0.174533 -0.0115373</pose>

<collision name='collision'>
<max_contacts>2</max_contacts>
<pose>0 -0.02505 0 1.5707 0 0</pose>
<geometry>
<cylinder>
<radius>0.01</radius>
<length>0.03095</length>
</cylinder>
</geometry>

</collision>
<visual name='visual'>
<geometry>
<mesh>
<uri>model://mpl_haptix_right_forearm/meshes/ring1.stl</uri>
</mesh>
</geometry>
<material>
<script>
<name>Gazebo/FlatBlack</name>
</script>
</material>
</visual>
<!--sensor name='ring1_contact_sensor' type='contact'>
<always_on>1</always_on>
<contact>
<collision>collision</collision>
</contact>
</sensor-->
</link>
<joint name='ring1' type='revolute'>
<child>ring1</child>
<parent>ring0</parent>
<axis>
<xyz>0.984742 -0.0113618 0.173648</xyz>


<use_parent_model_frame>1</use_parent_model_frame>
</axis>

</joint>

<link name='ring2'>
<pose>-0.0065449 -0.685726 0.137271 -1.14828e-13 -0.174533 -0.0115373</pose>

<collision name='collision'>
<max_contacts>2</max_contacts>
<pose>0 -0.01152 0 1.5707 0 0</pose>
<geometry>
<cylinder>
<length>0.029</length>
<radius>0.0075</radius>
</cylinder>
</geometry>

</collision>
<collision name='collision_1'>
<max_contacts>2</max_contacts>
<pose>0 -0.02302 0 0 0 0</pose>
<geometry>
<sphere>
<radius>0.0075</radius>
</sphere>
</geometry>

</collision>
<visual name='visual'>
<geometry>
<mesh>
<uri>model://mpl_haptix_right_forearm/meshes/ring2.stl</uri>
</mesh>
</geometry>
<material>
<script>
<name>Gazebo/FlatBlack</name>
</script>
</material>
</visual>
<!--sensor name='ring2_contact_sensor' type='contact'>
<always_on>1</always_on>
<contact>
<collision>collision</collision>
</contact>
</sensor-->
</link>
<joint name='ring2' type='revolute'>
<child>ring2</child>
<parent>ring1</parent>
<axis>
<xyz>0.984742 -0.0113618 0.173648</xyz>


<use_parent_model_frame>1</use_parent_model_frame>
</axis>

</joint>

<link name='ring3'>
<self_collide>true</self_collide>
<pose>-0.00745287 -0.710217 0.13716 -1.14821e-13 -0.174533 -0.0115373</pose>

<collision name='collision'>
<max_contacts>1</max_contacts>
<pose>0 -0.00688 0.0001 1.5707 0 0</pose>
<geometry>
<cylinder>
<length>0.01376</length>
<radius>0.0074</radius>
</cylinder>
</geometry>

</collision>
<collision name='collision_1'>
<max_contacts>1</max_contacts>
<pose>0 -0.015 0.0001 0 0 0</pose>
<geometry>
<sphere>
<radius>0.0072</radius>
</sphere>
</geometry>

</collision>
<visual name='visual'>
<geometry>
<mesh>
<uri>model://mpl_haptix_right_forearm/meshes/ring3.stl</uri>
</mesh>
</geometry>
<material>
<script>
<name>Gazebo/FlatBlack</name>
</script>
</material>
</visual>
<!--sensor name='ring3_contact_sensor' type='contact'>
<always_on>1</always_on>
<contact>
<collision>collision</collision>
<collision>collision_1</collision>
</contact>
</sensor-->
</link>
<joint name='ring3' type='revolute'>
<child>ring3</child>
<parent>ring2</parent>
<axis>
<xyz>0.984742 -0.0113618 0.173648</xyz>


<use_parent_model_frame>1</use_parent_model_frame>
</axis>

</joint>

<link name='thumb0'>
<pose>0.0374985 -0.578725 0.124974 0.0873761 -0.0305803 -0.276903</pose>

<collision name='collision'>
<max_contacts>2</max_contacts>
<pose>0.0200 -0.001 0.0015 0 0 0</pose>
<geometry>
<cylinder>
<length>0.023</length>
<radius>0.008221</radius>
</cylinder>
</geometry>

</collision>
<collision name='collision_1'>
<max_contacts>2</max_contacts>
<pose>0.01 -.001 0.0015 0 0 0</pose>
<geometry>
<box>
<size>0.0202 0.0155 0.023</size>
</box>
</geometry>

</collision>
<visual name='visual'>
<geometry>
<mesh>
<uri>model://mpl_haptix_right_forearm/meshes/thumb0.stl</uri>
</mesh>
</geometry>
<material>
<script>
<name>Gazebo/FlatBlack</name>
</script>
</material>
</visual>
</link>
<joint name='thumb0' type='revolute'>
<child>thumb0</child>
<parent>wristz</parent>
<axis>
<xyz>0.269769 0.958967 0.0872241</xyz>


<use_parent_model_frame>1</use_parent_model_frame>
</axis>

</joint>

<link name='thumb1'>
<pose>0.057306 -0.585356 0.126981 0.0873761 -0.0305803 -0.276903</pose>

<collision name='collision'>
<max_contacts>2</max_contacts>
<pose>-0.00056 0.00 -0.00025 0 0 0</pose>
<geometry>
<cylinder>
<length>0.0188</length>
<radius>0.00688</radius>
</cylinder>
</geometry>

</collision>
<collision name='collision_1'>
<max_contacts>2</max_contacts>
<pose>0.03381 0 0 0 0 0</pose>
<geometry>
<cylinder>
<length>0.02176</length>
<radius>0.00688</radius>
</cylinder>
</geometry>

</collision>
<collision name='collision_2'>
<max_contacts>2</max_contacts>
<pose>0.01613 0 0 0 0 0</pose>
<geometry>
<box>
<size>0.03273 0.01376 0.02176</size>
</box>
</geometry>

</collision>
<visual name='visual'>
<geometry>
<mesh>
<uri>model://mpl_haptix_right_forearm/meshes/thumb1.stl</uri>
</mesh>
</geometry>
<material>
<script>
<name>Gazebo/FlatBlack</name>
</script>
</material>
</visual>
<!--sensor name='thumb1_contact_sensor' type='contact'>
<always_on>1</always_on>
<contact>
<collision>collision</collision>
<collision>collision_1</collision>
<collision>collision_2</collision>
</contact>
</sensor-->
</link>
<joint name='thumb1' type='revolute'>
<child>thumb1</child>
<parent>thumb0</parent>
<axis>
<xyz>0.0531549 0.0756139 -0.995719</xyz>


<use_parent_model_frame>1</use_parent_model_frame>
</axis>

</joint>

<link name='thumb2'>
<pose>0.0895543 -0.594453 0.127266 0.0873761 -0.0305803 -0.276903</pose>

<collision name='collision'>
<max_contacts>2</max_contacts>
<pose>0.03415 0 0.001 0 0 0</pose>
<geometry>
<cylinder>
<radius>0.00679</radius>
<length>0.02236</length>
</cylinder>
</geometry>

</collision>
<collision name='collision_1'>
<max_contacts>2</max_contacts>
<pose>0.01493 0 0.001 0 0 0</pose>
<geometry>
<box>
<size>0.03095 0.015 0.02236</size>
</box>
</geometry>

</collision>
<visual name='visual'>
<geometry>
<mesh>
<uri>model://mpl_haptix_right_forearm/meshes/thumb2.stl</uri>
</mesh>
</geometry>
<material>
<script>
<name>Gazebo/FlatBlack</name>
</script>
</material>
</visual>
<!--sensor name='thumb2_contact_sensor' type='contact'>
<always_on>1</always_on>
<contact>
<collision>collision</collision>
<collision>collision_1</collision>
</contact>
</sensor-->
</link>
<joint name='thumb2' type='revolute'>
<child>thumb2</child>
<parent>thumb1</parent>
<axis>
<xyz>0.0531549 0.0756139 -0.995719</xyz>


<use_parent_model_frame>1</use_parent_model_frame>
</axis>

</joint>

<link name='thumb3'>
<self_collide>true</self_collide>
<pose>0.121705 -0.603689 0.129371 0.0873761 -0.0305803 -0.276903</pose>

<collision name='collision'>
<max_contacts>1</max_contacts>
<pose>0.01507 -0.00219 0.0001 0 0 0</pose>
<geometry>
<cylinder>
<length>0.01476</length>
<radius>0.0074</radius>
</cylinder>
</geometry>

</collision>
<collision name='collision_1'>
<max_contacts>1</max_contacts>
<pose>0.0195 0 0 0 0 0</pose>
<geometry>
<sphere>
<radius>0.008</radius>
</sphere>
</geometry>

</collision>
<visual name='visual'>
<geometry>
<mesh>
<uri>model://mpl_haptix_right_forearm/meshes/thumb3.stl</uri>
</mesh>
</geometry>
<material>
<script>
<name>Gazebo/FlatBlack</name>
</script>
</material>
</visual>
<!--sensor name='thumb3_contact_sensor' type='contact'>
<always_on>1</always_on>
<contact>
<collision>collision</collision>
<collision>collision_1</collision>
</contact>
</sensor-->
</link>
<joint name='thumb3' type='revolute'>
<child>thumb3</child>
<parent>thumb2</parent>
<axis>
<xyz>0.0531549 0.0756139 -0.995719</xyz>


<use_parent_model_frame>1</use_parent_model_frame>
</axis>
</joint>
	<plugin name="set_joint_position" filename="libset_joint_position_plugin.so">
		<topicName> /set_gazebo_joint_states </topicName>
		<joints>
        		wristy
        		wristx
        		wristz
        		badjnrt
        	</joints>
	</plugin>
</model>
</sdf>
