<robot name="mpl_haptix_right_forearm" xmlns:xacro="http://www.ros.org/wiki/xacro">
	<gazebo>
		<plugin name="set_joint_position" filename="libset_joint_position_plugin.so">
		<topicName> /hand_motion </topicName>
		<joints>
			wristx
			wristy
			wristz
        	</joints>
		</plugin>
	</gazebo>

	<!--Haptics' hand does not have the forearm attachment... I think.-->
	<!--joint name='elbow' type='fixed'>
		<child link="forearm"/>
		<parent link="arm_link"/>
		<origin xyz="0 0 0.15" rpy="0 0 0"/>
	</joint>
	<link name='forearm'>
		<origin xyz="0.00660504 -0.294573 0.119123" rpy="-1.21334e-13 2.77556e-17 -0.0115373"/>
		<collision name='collision'>
			<origin xyz="0 0 0.02855" rpy="0 0 0"/>
			<geometry>
				<cylinder radius="0.03567" length="0.0571"/>
			</geometry>
	
		</collision>
		<collision name='collision_1'>
			<origin xyz="0 -0.10745 0.016" rpy="1.5707 0 0"/>
			<geometry>
				<cylinder radius="0.035" length="0.148"/>
			</geometry>
	
		</collision>
		<visual name='visual'>
			<geometry>
				<mesh filename="package://lyra_gz/models/mpl_haptix_right_forearm/meshes/forearm.stl"/>
			</geometry>
		</visual>
	</link-->
	
	<link name='wristy'>
		<origin xyz="0.00449937 -0.479995 0.135123 -1.2164e-13 1.09079e-14 -0.0115373"/>
		<collision name='collision'>
			<origin xyz="0 -0.025 0" rpy="1.5707 0 0"/>
			<geometry>
				<cylinder radius="0.03447" length="0.05"/>
			</geometry>
		</collision>
		<visual name='visual'>
			<geometry>
				<mesh filename="package://lyra_gz/models/mpl_haptix_right_forearm/meshes/wristy.stl"/>
			</geometry>
		</visual>
		<inertial>
			<mass value="0.014" />
			<inertia
				ixx="0.00097298" ixy="0" ixz="0"
				iyy="0.00132536" iyz="0"
	        		izz="0.00097299"
	        	/>
	    	</inertial>
	</link>
	<joint name='wristy' type='revolute'>
		<limit lower="-1.5707" upper="1.5707" velocity="5.0" effort="1000"/>
		<child link="wristy"/>
		<parent link="arm_link"/>
		<axis xyz="0.011537 0.999933 0"/>
	</joint>
	
		<link name='wristx'>
		<origin xyz="0.003916 -0.527636 0.137161" rpy="-1.18962e-13 1.21847e-14 -0.0115373"/>
		<collision name='collision'>
			<origin xyz="0 0 -0.00314" rpy="0 0 0"/>
			<geometry>
				<cylinder radius="0.01473" length="0.04478"/>
			</geometry>
		</collision>
		<collision name='collision_1'>
			<origin xyz="0.02360 -0.02969 -0.00240" rpy="0 1.5707 0"/>
			<geometry>
				<cylinder radius="0.013175" length="0.005"/>
			</geometry>
		</collision>
		<collision name='collision_2'>
			<origin xyz="-0.02360 -0.02969 -0.00240" rpy="0 1.5707 0"/>
			<geometry>
				<cylinder radius="0.013175" length="0.005"/>
			</geometry>
		</collision>
		<visual name='visual'>
			<geometry>
				<mesh filename="package://lyra_gz/models/mpl_haptix_right_forearm/meshes/wristx.stl"/>
			</geometry>
		</visual>

		<inertial>
			<mass value="0.014" />
			<inertia
				ixx="0.00097298" ixy="0" ixz="0"
				iyy="0.00132536" iyz="0"
	        		izz="0.00097299"
	        	/>
	    	</inertial>
	</link>
	<joint name='wristx' type='revolute'>
		<limit lower="-1.5707" upper="1.5707" velocity="5.0" effort="1000"/>
		<child link="wristx"/>
		<parent link="wristy"/>
		<axis xyz="-1.35564e-14 -1.18814e-13 -1"/>
	</joint>
	
		<link name='wristz'>
		<origin xyz="0.00375708 -0.557636 0.135067" rpy="-2.87105e-13 1.42109e-14 -0.0115373"/>
		<collision name='collision'>
			<origin xyz="0.00207 -0.00047 0.00046" rpy="1.5707 0 1.5707"/>
			<geometry>
				<cylinder radius="0.01411" length="0.04482"/>
			</geometry>
		</collision>
		<collision name='collision_palm'>
			<max_contacts>4</max_contacts>
			<origin xyz="0.002 -0.03739 0" rpy="0 0 0"/>
			<geometry>
				<box size="0.07928 0.08316 0.04402"/>
			</geometry>
		</collision>
		<collision name="palmEdge">
			<max_contacts>4</max_contacts>
			<origin xyz="-0.028 -0.03 0" rpy="1.57 0 -0.1"/>
			<geometry>
				<cylinder radius="0.01" length="0.060"/>
			</geometry>
		</collision>
		<!-- Dorsal surface (top) -->
		<collision name="handTop">
			<max_contacts>4</max_contacts>
			<origin xyz="0.002 -0.045 0.01" rpy="0 0 0"/>
			<geometry>
				<box size="0.075 0.08 0.02"/>
			</geometry>
		</collision>
		<!-- Palm 0 (closer to thumb) -->
		<collision name="palm0">
			<max_contacts>4</max_contacts>
			<origin xyz="0.023 -0.04 -0.012" rpy="0 0 0.1"/>
			<geometry>
				<box size="0.037 0.07 0.02"/>
			</geometry>
		</collision>
			<!-- Palm 1 (closer to pinky) -->
			<collision name="palm1">
			<max_contacts>4</max_contacts>
			<origin xyz="-0.018 -0.04 -0.012" rpy="0 0 0"/>
			<geometry>
				<box size="0.037 0.07 0.02"/>
			</geometry>
		</collision>
		<visual name='visual'>
			<geometry>
				<mesh filename="package://lyra_gz/models/mpl_haptix_right_forearm/meshes/wristz.stl"/>
			</geometry>
		</visual>
		<visual name='visual_palm'>
			<origin xyz="0.025625 0 0" rpy="1.7427e-13 8.3267e-17 -3.1876e-16"/>
			<geometry>
				<mesh filename="package://lyra_gz/models/mpl_haptix_right_forearm/meshes/palm.stl"/>
			</geometry>
		</visual>
		<!--sensor name='palm0_contact_sensor' type='contact'>
			<always_on>1</always_on>
			<contact>
				<collision>palm0</collision>
			</contact>
		</sensor-->
		<!--sensor name='palm1_contact_sensor' type='contact'>
			<always_on>1</always_on>
			<contact>
				<collision>palm1</collision>
			</contact>
		</sensor-->
		<!--sensor name='palmEdge_contact_sensor' type='contact'>
			<always_on>1</always_on>
			<contact>
				<collision>palmEdge</collision>
			</contact>
		</sensor-->
		<!--sensor name='handTop_contact_sensor' type='contact'>
			<always_on>1</always_on>
			<contact>
				<collision>handTop</collision>
			</contact>
		</sensor-->

		<inertial>
			<mass value="0.014" />
			<inertia
				ixx="0.00097298" ixy="0" ixz="0"
				iyy="0.00132536" iyz="0"
	        		izz="0.00097299"
	        	/>
	    	</inertial>
	</link>
	<joint name='wristz' type='revolute'>
		<limit lower="-1.5707" upper="1.5707" velocity="5.0" effort="1000"/>
		<child link="wristz"/>
		<parent link="wristx"/>
		<axis xyz="0.999933 -0.011537 -1.42109e-14"/>
	</joint>
	
		<link name='index0'>
<origin xyz="0.0384854 -0.623842 0.136079" rpy="-1.14726e-13 0.174533 -0.0115373"/>

<collision name='collision'>
<max_contacts>1</max_contacts>
<origin xyz="0 -0.01339 0" rpy="1.5707 0 0"/>
<geometry>
<cylinder length="0.028" radius="0.01"/>
</geometry>

</collision>
<visual name='visual'>
<geometry>
<mesh filename="package://lyra_gz/models/mpl_haptix_right_forearm/meshes/index0.stl"/>
</geometry>

<!--material>
<script>
<name>Gazebo/FlatBlack</name>
</script>
</material-->
</visual>

		<inertial>
			<mass value="0.014" />
			<inertia
				ixx="0.00097298" ixy="0" ixz="0"
				iyy="0.00132536" iyz="0"
	        		izz="0.00097299"
	        	/>
	    	</inertial>
	</link>
<joint name='index0' type='revolute'>
		<limit lower="-1.5707" upper="1.5707" velocity="5.0" effort="1000"/>
<child link="index0"/>
<parent link="wristz"/>
<axis xyz="-0.173637 0.00200338 -0.984808"/>
</joint>

	<link name='index1'>
<origin xyz="0.0383394 -0.641841 0.136068" rpy="-1.1474e-13 0.174533 -0.0115373"/>

<collision name='collision'>
<max_contacts>2</max_contacts>
<origin xyz="0 -0.02782 0" rpy="1.5707 0 0"/>
<geometry>
<cylinder radius="0.01" length="0.02781"/>

</geometry>

</collision>
<visual name='visual'>
<geometry>
<mesh filename="package://lyra_gz/models/mpl_haptix_right_forearm/meshes/index1.stl"/>
</geometry>
<!--material>
<script>
<name>Gazebo/FlatBlack</name>
</script>
</material-->
</visual>
<!--sensor name='index1_contact_sensor' type='contact'>
<always_on>1</always_on>
<contact>
<collision>collision</collision>
</contact>
</sensor-->

		<inertial>
			<mass value="0.014" />
			<inertia
				ixx="0.00097298" ixy="0" ixz="0"
				iyy="0.00132536" iyz="0"
	        		izz="0.00097299"
	        	/>
	    	</inertial>
	</link>
<joint name='index1' type='revolute'>
		<limit lower="-1.5707" upper="1.5707" velocity="5.0" effort="1000"/>
<child link="index1"/>
<parent link="index0"/>
<axis xyz="0.984742 -0.0113618 -0.173648"/>
</joint>

	<link name='index2'>
<origin xyz="0.0389938 -0.685352 0.136372" rpy="-1.1445e-13 0.174533 -0.0115373"/>

<collision name='collision'>
<max_contacts>2</max_contacts>
<origin xyz="0 -0.01152 0" rpy="1.5707 0 0"/>
<geometry>
<cylinder length="0.029" radius="0.0075"/>
</geometry>

</collision>
<collision name='collision_1'>
<max_contacts>2</max_contacts>
<origin xyz="0 -0.02502 0" rpy="0 0 0"/>
<geometry>
<sphere radius="0.0075"/>
</geometry>

</collision>
<visual name='visual'>
<geometry>
<mesh filename="package://lyra_gz/models/mpl_haptix_right_forearm/meshes/index2.stl"/>
</geometry>
<!--material>
<script>
<name>Gazebo/FlatBlack</name>
</script>
</material-->
</visual>
<!--sensor name='index2_contact_sensor' type='contact'>
<always_on>1</always_on>
<contact>
<collision>collision</collision>
<collision>collision_1</collision>
</contact>
</sensor-->

		<inertial>
			<mass value="0.014" />
			<inertia
				ixx="0.00097298" ixy="0" ixz="0"
				iyy="0.00132536" iyz="0"
	        		izz="0.00097299"
	        	/>
	    	</inertial>
	</link>
<joint name='index2' type='revolute'>
		<limit lower="-1.5707" upper="1.5707" velocity="5.0" effort="1000"/>
<child link="index2"/>
<parent link="index1"/>
<axis xyz="0.984742 -0.0113618 -0.173648"/>
</joint>

	<link name='index3'>
<self_collide>true</self_collide>
<origin xyz="0.0380858 -0.709843 0.136482" rpy="-1.15476e-13 0.174533 -0.0115373"/>

<collision name='collision'>
<max_contacts>1</max_contacts>
<origin xyz="0 -0.00688 0.0001" rpy="1.5707 0 0"/>
<geometry>
<cylinder length="0.01376" radius="0.0074"/>
</geometry>

</collision>
<collision name='collision_1'>
<max_contacts>1</max_contacts>
<origin xyz="0 -0.015 0.0001" rpy="0 0 0"/>
<geometry>
<sphere radius="0.0072"/>
</geometry>

</collision>
<visual name='visual'>
<geometry>
<mesh filename="package://lyra_gz/models/mpl_haptix_right_forearm/meshes/index3.stl"/>
</geometry>
<!--material>
<script>
<name>Gazebo/FlatBlack</name>
</script>
</material-->
</visual>
<!--sensor name='index3_contact_sensor' type='contact'>
<always_on>1</always_on>
<contact>
<collision>collision</collision>
<collision>collision_1</collision>
</contact>
</sensor-->

		<inertial>
			<mass value="0.014" />
			<inertia
				ixx="0.00097298" ixy="0" ixz="0"
				iyy="0.00132536" iyz="0"
	        		izz="0.00097299"
	        	/>
	    	</inertial>
	</link>
<joint name='index3' type='revolute'>
		<limit lower="-1.5707" upper="1.5707" velocity="5.0" effort="1000"/>
<child link="index3"/>
<parent link="index2"/>
<axis xyz="0.984742 -0.0113618 -0.173648"/>
</joint>

	<link name='middle0'>
<origin xyz="0.0156685 -0.63568 0.140513" rpy="0.0872665 1.4183e-14 -0.0115373"/>

<collision name='collision'>
<max_contacts>1</max_contacts>
<origin xyz="0 -0.01339 0" rpy="1.5707 0 0"/>
<geometry>
<cylinder length="0.028" radius="0.01"/>
</geometry>

</collision>
<visual name='visual'>
<geometry>
<mesh filename="package://lyra_gz/models/mpl_haptix_right_forearm/meshes/middle0.stl"/>
</geometry>
<!--material>
<script>
<name>Gazebo/FlatBlack</name>
</script>
</material-->
</visual>

		<inertial>
			<mass value="0.014" />
			<inertia
				ixx="0.00097298" ixy="0" ixz="0"
				iyy="0.00132536" iyz="0"
	        		izz="0.00097299"
	        	/>
	    	</inertial>
	</link>
<joint name='middle0' type='revolute'>
		<limit lower="-1.5707" upper="1.5707" velocity="5.0" effort="1000"/>
<child link="middle0"/>
<parent link="wristz"/>
<axis xyz="0.00100552 0.0871499 -0.996195"/>
</joint>

	<link name='middle1'>
<origin xyz="0.0155242 -0.653612 0.138944" rpy="0.0872665 1.43013e-14 -0.0115373"/>

<collision name='collision'>
<max_contacts>2</max_contacts>
<origin xyz="0 -0.025 0" rpy="1.5707 0 0"/>
<geometry>
<cylinder radius="0.01" length="0.03459"/>
</geometry>

</collision>
<visual name='visual'>
<geometry>
<mesh filename="package://lyra_gz/models/mpl_haptix_right_forearm/meshes/middle1.stl"/>
</geometry>
<!--material>
<script>
<name>Gazebo/FlatBlack</name>
</script>
</material-->
</visual>
<!--sensor name='middle1_contact_sensor' type='contact'>
<always_on>1</always_on>
<contact>
<collision>collision</collision>
</contact>
</sensor-->

		<inertial>
			<mass value="0.014" />
			<inertia
				ixx="0.00097298" ixy="0" ixz="0"
				iyy="0.00132536" iyz="0"
	        		izz="0.00097299"
	        	/>
	    	</inertial>
	</link>
<joint name='middle1' type='revolute'>
		<limit lower="-1.5707" upper="1.5707" velocity="5.0" effort="1000"/>
<child link="middle1"/>
<parent link="middle0"/>
<axis xyz="0.999933 -0.011537 -1.43013e-14"/>
</joint>

	<link name='middle2'>
<origin xyz="0.0161097 -0.696999 0.135651" rpy="0.0872665 1.32728e-14 -0.0115373"/>

<collision name='collision'>
<max_contacts>2</max_contacts>
<origin xyz="0 -0.01152 0" rpy="1.5707 0 0"/>
<geometry>
<cylinder length="0.029" radius="0.0075"/>
</geometry>

</collision>
<collision name='collision_1'>
<max_contacts>2</max_contacts>
<origin xyz="0 -0.02302 0" rpy="0 0 0"/>
<geometry>
<sphere radius="0.0075"/>
</geometry>

</collision>
<visual name='visual'>
<geometry>
<mesh filename="package://lyra_gz/models/mpl_haptix_right_forearm/meshes/middle2.stl"/>
</geometry>
<!--material>
<script>
<name>Gazebo/FlatBlack</name>
</script>
</material-->
</visual>
<!--sensor name='middle2_contact_sensor' type='contact'>
<always_on>1</always_on>
<contact>
<collision>collision</collision>
<collision>collision_1</collision>
</contact>
</sensor-->

		<inertial>
			<mass value="0.014" />
			<inertia
				ixx="0.00097298" ixy="0" ixz="0"
				iyy="0.00132536" iyz="0"
	        		izz="0.00097299"
	        	/>
	    	</inertial>
	</link>
<joint name='middle2' type='revolute'>
		<limit lower="-1.5707" upper="1.5707" velocity="5.0" effort="1000"/>
<child link="middle2"/>
<parent link="middle1"/>
<axis xyz="0.999933 -0.011537 -1.32727e-14"/>
</joint>

	<link name='middle3'>
<self_collide>true</self_collide>
<origin xyz="0.0151931 -0.721397 0.133515" rpy="0.0872665 1.51577e-14 -0.0115373"/>

<collision name='collision'>
<max_contacts>1</max_contacts>
<origin xyz="0 -0.00688 0.0001" rpy="1.5707 0 0"/>
<geometry>
<cylinder length="0.01376" radius="0.0074"/>
</geometry>

</collision>
<collision name='collision_1'>
<max_contacts>1</max_contacts>
<origin xyz="0 -0.015 0.0001" rpy="0 0 0"/>
<geometry>
<sphere radius="0.0072"/>
</geometry>

</collision>
<visual name='visual'>
<geometry>
<mesh filename="package://lyra_gz/models/mpl_haptix_right_forearm/meshes/middle3.stl"/>
</geometry>
<!--material>
<script>
<name>Gazebo/FlatBlack</name>
</script>
</material-->
</visual>
<!--sensor name='middle3_contact_sensor' type='contact'>
<always_on>1</always_on>
<contact>
<collision>collision</collision>
<collision>collision_1</collision>
</contact>
</sensor-->

		<inertial>
			<mass value="0.014" />
			<inertia
				ixx="0.00097298" ixy="0" ixz="0"
				iyy="0.00132536" iyz="0"
	        		izz="0.00097299"
	        	/>
	    	</inertial>
	</link>
<joint name='middle3' type='revolute'>
		<limit lower="-1.5707" upper="1.5707" velocity="5.0" effort="1000"/>
<child link="middle3"/>
<parent link="middle2"/>
<axis xyz="0.999933 -0.011537 -1.51577e-14"/>
</joint>

	<link name='pinky0'>
<origin xyz="-0.0275009 -0.61268 0.129428" rpy="-1.14942e-13 -0.174533 -0.0115373"/>

<collision name='collision'>
<max_contacts>1</max_contacts>
<origin xyz="0 -0.01339 0" rpy="1.5707 0 0"/>
<geometry>
<cylinder length="0.028" radius="0.01"/>
</geometry>

</collision>
<visual name='visual'>
<geometry>
<mesh filename="package://lyra_gz/models/mpl_haptix_right_forearm/meshes/pinky0.stl"/>
</geometry>
<!--material>
<script>
<name>Gazebo/FlatBlack</name>
</script>
</material-->
</visual>

		<inertial>
			<mass value="0.014" />
			<inertia
				ixx="0.00097298" ixy="0" ixz="0"
				iyy="0.00132536" iyz="0"
	        		izz="0.00097299"
	        	/>
	    	</inertial>
	</link>
<joint name='pinky0' type='revolute'>
		<limit lower="-1.5707" upper="1.5707" velocity="5.0" effort="1000"/>
<child link="pinky0"/>
<parent link="wristz"/>
<axis xyz="0.173637 -0.00200338 -0.984808"/>
</joint>

	<link name='pinky1'>
<origin xyz="-0.0276458 -0.630579 0.129439" rpy="-1.14943e-13 -0.174533 -0.0115373"/>

<collision name='collision'>
<max_contacts>2</max_contacts>
<origin xyz="0 -0.02082 0" rpy="1.5707 0 0"/>
<geometry>
<cylinder radius="0.01" length="0.02381"/>
</geometry>

</collision>
<visual name='visual'>
<geometry>
<mesh filename="package://lyra_gz/models/mpl_haptix_right_forearm/meshes/pinky1.stl"/>
</geometry>
<!--material>
<script>
<name>Gazebo/FlatBlack</name>
</script>
</material-->
</visual>
<!--sensor name='pinky1_contact_sensor' type='contact'>
<always_on>1</always_on>
<contact>
<collision>collision</collision>
</contact>
</sensor-->

		<inertial>
			<mass value="0.014" />
			<inertia
				ixx="0.00097298" ixy="0" ixz="0"
				iyy="0.00132536" iyz="0"
	        		izz="0.00097299"
	        	/>
	    	</inertial>
	</link>
<joint name='pinky1' type='revolute'>
		<limit lower="-1.5707" upper="1.5707" velocity="5.0" effort="1000"/>
<child link="pinky1"/>
<parent link="pinky0"/>
<axis xyz="0.984742 -0.0113618 0.173648"/>
</joint>

	<link name='pinky2'>
<origin xyz="-0.0275441 -0.663582 0.130032" rpy="-1.14415e-13 -0.174533 -0.0115373"/>

<collision name='collision'>
<max_contacts>2</max_contacts>
<origin xyz="0 -0.0076 0" rpy="1.5707 0 0"/>
<geometry>
<cylinder length="0.029" radius="0.0075"/>
</geometry>

</collision>
<visual name='visual'>
<geometry>
<mesh filename="package://lyra_gz/models/mpl_haptix_right_forearm/meshes/pinky2.stl"/>
</geometry>
<!--material>
<script>
<name>Gazebo/FlatBlack</name>
</script>
</material-->
</visual>
<!--sensor name='pinky2_contact_sensor' type='contact'>
<always_on>1</always_on>
<contact>
<collision>collision</collision>
</contact>
</sensor-->

		<inertial>
			<mass value="0.014" />
			<inertia
				ixx="0.00097298" ixy="0" ixz="0"
				iyy="0.00132536" iyz="0"
	        		izz="0.00097299"
	        	/>
	    	</inertial>
	</link>
<joint name='pinky2' type='revolute'>
		<limit lower="-1.5707" upper="1.5707" velocity="5.0" effort="1000"/>
<child link="pinky2"/>
<parent link="pinky1"/>
<axis xyz="0.984742 -0.0113618 0.173648"/>
</joint>

	<link name='pinky3'>
<self_collide>true</self_collide>
<origin xyz="-0.0277931 -0.681081 0.130023" rpy="-1.14622e-13 -0.174533 -0.0115373"/>

<collision name='collision'>
<max_contacts>1</max_contacts>
<origin xyz="0 -0.00688 0.0001" rpy="1.5707 0 0"/>
<geometry>
<cylinder length="0.01376" radius="0.0074"/>
</geometry>

</collision>
<collision name='collision_1'>
<max_contacts>1</max_contacts>
<origin xyz="0 -0.015 0.0001" rpy="0 0 0"/>
<geometry>
<sphere radius="0.0072"/>
</geometry>

</collision>
<visual name='visual'>
<geometry>
<mesh filename="package://lyra_gz/models/mpl_haptix_right_forearm/meshes/pinky3.stl"/>
</geometry>
<!--material>
<script>
<name>Gazebo/FlatBlack</name>
</script>
</material-->
</visual>
<!--sensor name='pinky3_contact_sensor' type='contact'>
<always_on>1</always_on>
<contact>
<collision>collision</collision>
<collision>collision_1</collision>
</contact>
</sensor-->

		<inertial>
			<mass value="0.014" />
			<inertia
				ixx="0.00097298" ixy="0" ixz="0"
				iyy="0.00132536" iyz="0"
	        		izz="0.00097299"
	        	/>
	    	</inertial>
	</link>
<joint name='pinky3' type='revolute'>
		<limit lower="-1.5707" upper="1.5707" velocity="5.0" effort="1000"/>
<child link="pinky3"/>
<parent link="pinky2"/>
<axis xyz="0.984742 -0.0113618 0.173648"/>
</joint>

	<link name='ring0'>
<origin xyz="-0.00687963 -0.624218 0.136579" rpy="-1.14553e-13 -0.174533 -0.0115373"/>

<collision name='collision'>
<max_contacts>1</max_contacts>
<origin xyz="0 -0.01339 0" rpy="1.5707 0 0"/>
<geometry>
<cylinder length="0.028" radius="0.01"/>
</geometry>

</collision>
<visual name='visual'>
<geometry>
<mesh filename="package://lyra_gz/models/mpl_haptix_right_forearm/meshes/ring0.stl"/>
</geometry>
<!--material>
<script>
<name>Gazebo/FlatBlack</name>
</script>
</material-->
</visual>

		<inertial>
			<mass value="0.014" />
			<inertia
				ixx="0.00097298" ixy="0" ixz="0"
				iyy="0.00132536" iyz="0"
	        		izz="0.00097299"
	        	/>
	    	</inertial>
	</link>
<joint name='ring0' type='revolute'>
		<limit lower="-1.5707" upper="1.5707" velocity="5.0" effort="1000"/>
<child link="ring0"/>
<parent link="wristz"/>
<axis xyz="0.173637 -0.00200338 -0.984808"/>
</joint>

	<link name='ring1'>
<origin xyz="-0.00702565 -0.642218 0.13659" rpy="-1.14538e-13 -0.174533 -0.0115373"/>

<collision name='collision'>
<max_contacts>2</max_contacts>
<origin xyz="0 -0.02505 0" rpy="1.5707 0 0"/>
<geometry>
<cylinder radius="0.01" length="0.03095"/>
</geometry>

</collision>
<visual name='visual'>
<geometry>
<mesh filename="package://lyra_gz/models/mpl_haptix_right_forearm/meshes/ring1.stl"/>
</geometry>
<!--material>
<script>
<name>Gazebo/FlatBlack</name>
</script>
</material-->
</visual>
<!--sensor name='ring1_contact_sensor' type='contact'>
<always_on>1</always_on>
<contact>
<collision>collision</collision>
</contact>
</sensor-->

		<inertial>
			<mass value="0.014" />
			<inertia
				ixx="0.00097298" ixy="0" ixz="0"
				iyy="0.00132536" iyz="0"
	        		izz="0.00097299"
	        	/>
	    	</inertial>
	</link>
<joint name='ring1' type='revolute'>
		<limit lower="-1.5707" upper="1.5707" velocity="5.0" effort="1000"/>
<child link="ring1"/>
<parent link="ring0"/>
<axis xyz="0.984742 -0.0113618 0.173648"/>
</joint>

	<link name='ring2'>
<origin xyz="-0.0065449 -0.685726 0.137271" rpy="-1.14828e-13 -0.174533 -0.0115373"/>

<collision name='collision'>
<max_contacts>2</max_contacts>
<origin xyz="0 -0.01152 0" rpy="1.5707 0 0"/>
<geometry>
<cylinder length="0.029" radius="0.0075"/>
</geometry>

</collision>
<collision name='collision_1'>
<max_contacts>2</max_contacts>
<origin xyz="0 -0.02302 0" rpy="0 0 0"/>
<geometry>
<sphere radius="0.0075"/>
</geometry>

</collision>
<visual name='visual'>
<geometry>
<mesh filename="package://lyra_gz/models/mpl_haptix_right_forearm/meshes/ring2.stl"/>
</geometry>
<!--material>
<script>
<name>Gazebo/FlatBlack</name>
</script>
</material-->
</visual>
<!--sensor name='ring2_contact_sensor' type='contact'>
<always_on>1</always_on>
<contact>
<collision>collision</collision>
</contact>
</sensor-->

		<inertial>
			<mass value="0.014" />
			<inertia
				ixx="0.00097298" ixy="0" ixz="0"
				iyy="0.00132536" iyz="0"
	        		izz="0.00097299"
	        	/>
	    	</inertial>
	</link>
<joint name='ring2' type='revolute'>
		<limit lower="-1.5707" upper="1.5707" velocity="5.0" effort="1000"/>
<child link="ring2"/>
<parent link="ring1"/>
<axis xyz="0.984742 -0.0113618 0.173648"/>
</joint>

	<link name='ring3'>
<self_collide>true</self_collide>
<origin xyz="-0.00745287 -0.710217 0.13716" rpy="-1.14821e-13 -0.174533 -0.0115373"/>

<collision name='collision'>
<max_contacts>1</max_contacts>
<origin xyz="0 -0.00688 0.0001" rpy="1.5707 0 0"/>
<geometry>
<cylinder length="0.01376" radius="0.0074"/>
</geometry>

</collision>
<collision name='collision_1'>
<max_contacts>1</max_contacts>
<origin xyz="0 -0.015 0.0001" rpy="0 0 0"/>
<geometry>
<sphere radius="0.0072"/>
</geometry>

</collision>
<visual name='visual'>
<geometry>
<mesh filename="package://lyra_gz/models/mpl_haptix_right_forearm/meshes/ring3.stl"/>
</geometry>
<!--material>
<script>
<name>Gazebo/FlatBlack</name>
</script>
</material-->
</visual>
<!--sensor name='ring3_contact_sensor' type='contact'>
<always_on>1</always_on>
<contact>
<collision>collision</collision>
<collision>collision_1</collision>
</contact>
</sensor-->

		<inertial>
			<mass value="0.014" />
			<inertia
				ixx="0.00097298" ixy="0" ixz="0"
				iyy="0.00132536" iyz="0"
	        		izz="0.00097299"
	        	/>
	    	</inertial>
	</link>
<joint name='ring3' type='revolute'>
		<limit lower="-1.5707" upper="1.5707" velocity="5.0" effort="1000"/>
<child link="ring3"/>
<parent link="ring2"/>
<axis xyz="0.984742 -0.0113618 0.173648"/>
</joint>

	<link name='thumb0'>
<origin xyz="0.0374985 -0.578725 0.124974" rpy="0.0873761 -0.0305803 -0.276903"/>

<collision name='collision'>
<max_contacts>2</max_contacts>
<origin xyz="0.0200 -0.001 0.0015" rpy="0 0 0"/>
<geometry>
<cylinder length="0.023" radius="0.008221"/>
</geometry>

</collision>
<collision name='collision_1'>
<max_contacts>2</max_contacts>
<origin xyz="0.01 -.001 0.0015" rpy="0 0 0"/>
<geometry>
<box size="0.0202 0.0155 0.023"/>
</geometry>

</collision>
<visual name='visual'>
<geometry>
<mesh filename="package://lyra_gz/models/mpl_haptix_right_forearm/meshes/thumb0.stl"/>
</geometry>
<!--material>
<script>
<name>Gazebo/FlatBlack</name>
</script>
</material-->
</visual>

		<inertial>
			<mass value="0.014" />
			<inertia
				ixx="0.00097298" ixy="0" ixz="0"
				iyy="0.00132536" iyz="0"
	        		izz="0.00097299"
	        	/>
	    	</inertial>
	</link>
<joint name='thumb0' type='revolute'>
		<limit lower="-1.5707" upper="1.5707" velocity="5.0" effort="1000"/>
<child link="thumb0"/>
<parent link="wristz"/>
<axis xyz="0.269769 0.958967 0.0872241"/>
</joint>

	<link name='thumb1'>
<origin xyz="0.057306 -0.585356 0.126981" rpy="0.0873761 -0.0305803 -0.276903"/>

<collision name='collision'>
<max_contacts>2</max_contacts>
<origin xyz="-0.00056 0.00 -0.00025" rpy="0 0 0"/>
<geometry>
<cylinder length="0.0188" radius="0.00688"/>
</geometry>

</collision>
<collision name='collision_1'>
<max_contacts>2</max_contacts>
<origin xyz="0.03381 0 0" rpy="0 0 0"/>
<geometry>
<cylinder length="0.02176" radius="0.00688"/>
</geometry>

</collision>
<collision name='collision_2'>
<max_contacts>2</max_contacts>
<origin xyz="0.01613 0 0" rpy="0 0 0"/>
<geometry>
<box size="0.03273 0.01376 0.02176"/>
</geometry>

</collision>
<visual name='visual'>
<geometry>
<mesh filename="package://lyra_gz/models/mpl_haptix_right_forearm/meshes/thumb1.stl"/>
</geometry>
<!--material>
<script>
<name>Gazebo/FlatBlack</name>
</script>
</material-->
</visual>
<!--sensor name='thumb1_contact_sensor' type='contact'>
<always_on>1</always_on>
<contact>
<collision>collision</collision>
<collision>collision_1</collision>
<collision>collision_2</collision>
</contact>
</sensor-->

		<inertial>
			<mass value="0.014" />
			<inertia
				ixx="0.00097298" ixy="0" ixz="0"
				iyy="0.00132536" iyz="0"
	        		izz="0.00097299"
	        	/>
	    	</inertial>
	</link>
<joint name='thumb1' type='revolute'>
		<limit lower="-1.5707" upper="1.5707" velocity="5.0" effort="1000"/>
<child link="thumb1"/>
<parent link="thumb0"/>
<axis xyz="0.0531549 0.0756139 -0.995719"/>
</joint>

	<link name='thumb2'>
<origin xyz="0.0895543 -0.594453 0.127266" rpy="0.0873761 -0.0305803 -0.276903"/>

<collision name='collision'>
<max_contacts>2</max_contacts>
<origin xyz="0.03415 0 0.001" rpy="0 0 0"/>
<geometry>
<cylinder radius="0.00679" length="0.02236"/>
</geometry>

</collision>
<collision name='collision_1'>
<max_contacts>2</max_contacts>
<origin xyz="0.01493 0 0.001" rpy="0 0 0"/>
<geometry>
<box size="0.03095 0.015 0.02236"/>
</geometry>

</collision>
<visual name='visual'>
<geometry>
<mesh filename="package://lyra_gz/models/mpl_haptix_right_forearm/meshes/thumb2.stl"/>
</geometry>
<!--material>
<script>
<name>Gazebo/FlatBlack</name>
</script>
</material-->
</visual>
<!--sensor name='thumb2_contact_sensor' type='contact'>
<always_on>1</always_on>
<contact>
<collision>collision</collision>
<collision>collision_1</collision>
</contact>
</sensor-->

		<inertial>
			<mass value="0.014" />
			<inertia
				ixx="0.00097298" ixy="0" ixz="0"
				iyy="0.00132536" iyz="0"
	        		izz="0.00097299"
	        	/>
	    	</inertial>
	</link>
<joint name='thumb2' type='revolute'>
		<limit lower="-1.5707" upper="1.5707" velocity="5.0" effort="1000"/>
<child link="thumb2"/>
<parent link="thumb1"/>
<axis xyz="0.0531549 0.0756139 -0.995719"/>
</joint>

	<link name='thumb3'>
<self_collide>true</self_collide>
<origin xyz="0.121705 -0.603689 0.129371" rpy="0.0873761 -0.0305803 -0.276903"/>

<collision name='collision'>
<max_contacts>1</max_contacts>
<origin xyz="0.01507 -0.00219 0.0001" rpy="0 0 0"/>
<geometry>
<cylinder length="0.01476" radius="0.0074"/>
</geometry>

</collision>
<collision name='collision_1'>
<max_contacts>1</max_contacts>
<origin xyz="0.0195 0 0" rpy="0 0 0"/>
<geometry>
<sphere radius="0.008"/>
</geometry>

</collision>
<visual name='visual'>
<geometry>
<mesh filename="package://lyra_gz/models/mpl_haptix_right_forearm/meshes/thumb3.stl"/>
</geometry>
<!--material>
<script>
<name>Gazebo/FlatBlack</name>
</script>
</material-->
</visual>
<!--sensor name='thumb3_contact_sensor' type='contact'>
<always_on>1</always_on>
<contact>
<collision>collision</collision>
<collision>collision_1</collision>
</contact>
</sensor-->

		<inertial>
			<mass value="0.014" />
			<inertia
				ixx="0.00097298" ixy="0" ixz="0"
				iyy="0.00132536" iyz="0"
	        		izz="0.00097299"
	        	/>
	    	</inertial>
	</link>
<joint name='thumb3' type='revolute'>
		<limit lower="-1.5707" upper="1.5707" velocity="5.0" effort="1000"/>
<child link="thumb3"/>
<parent link="thumb2"/>
<axis xyz="0.0531549 0.0756139 -0.995719"/>
</joint>
</robot>
